[2018-05-25 16:51:10,091][Thread-1:3476][task_id:collect][views.py:282][INFO][得到年和月的参数啦！！！！]
[2018-05-25 16:54:36,822][Thread-1:7356][task_id:django.request][exception.py:135][ERROR][Internal Server Error: /blog/xiaohei/archive/2018x05/]
Traceback (most recent call last):
  File "C:\Python36\lib\site-packages\django\core\handlers\exception.py", line 41, in inner
    response = get_response(request)
  File "C:\Python36\lib\site-packages\django\core\handlers\base.py", line 187, in _get_response
    response = self.process_exception_by_middleware(e, request)
  File "C:\Python36\lib\site-packages\django\core\handlers\base.py", line 185, in _get_response
    response = wrapped_callback(request, *callback_args, **callback_kwargs)
  File "D:\python10\day78\bbs\blog\views.py", line 281, in home
    year, month = args[1].split("-")
ValueError: not enough values to unpack (expected 2, got 1)
[2018-05-25 16:56:32,723][Thread-1:8112][task_id:blog.views][views.py:290][ERROR][请求访问的日期归档格式不正确！！！]
[2018-05-25 16:56:39,854][Thread-3:6132][task_id:django.request][exception.py:135][ERROR][Internal Server Error: /blog/xiaohei/archive/2018-05-/]
Traceback (most recent call last):
  File "C:\Python36\lib\site-packages\django\core\handlers\exception.py", line 41, in inner
    response = get_response(request)
  File "C:\Python36\lib\site-packages\django\core\handlers\base.py", line 187, in _get_response
    response = self.process_exception_by_middleware(e, request)
  File "C:\Python36\lib\site-packages\django\core\handlers\base.py", line 185, in _get_response
    response = wrapped_callback(request, *callback_args, **callback_kwargs)
  File "D:\python10\day78\bbs\blog\views.py", line 282, in home
    year, month = args[1].split("-")
ValueError: too many values to unpack (expected 2)
[2018-05-25 16:57:44,421][Thread-1:5596][task_id:blog.views][views.py:290][WARNING][请求访问的日期归档格式不正确！！！]
[2018-05-25 16:57:44,421][Thread-1:5596][task_id:blog.views][views.py:291][WARNING][too many values to unpack (expected 2)]
[2018-05-28 08:41:53,683][Thread-11:6448][task_id:django.request][base.py:152][WARNING][Not Found: /favicon.ico]
[2018-05-28 08:42:19,143][Thread-13:6564][task_id:django.request][base.py:152][WARNING][Not Found: /blog/]
[2018-05-28 10:12:02,507][Thread-186:7096][task_id:requests.packages.urllib3.connectionpool][connectionpool.py:214][INFO][Starting new HTTP connection (1): api.geetest.com]
[2018-05-28 10:12:23,218][Thread-188:2116][task_id:requests.packages.urllib3.connectionpool][connectionpool.py:214][INFO][Starting new HTTP connection (1): api.geetest.com]
[2018-05-28 10:32:54,986][Thread-12:6200][task_id:django.security.csrf][csrf.py:160][WARNING][Forbidden (CSRF token missing or incorrect.): /blog/up_down]
[2018-05-28 10:35:21,048][Thread-33:192][task_id:blog.views][views.py:249][WARNING][又有人访问不存在页面了...]
[2018-05-28 10:47:42,388][Thread-12:5696][task_id:django.request][exception.py:135][ERROR][Internal Server Error: /blog/up_down/]
Traceback (most recent call last):
  File "C:\Python36\lib\site-packages\django\core\handlers\exception.py", line 41, in inner
    response = get_response(request)
  File "C:\Python36\lib\site-packages\django\core\handlers\base.py", line 187, in _get_response
    response = self.process_exception_by_middleware(e, request)
  File "C:\Python36\lib\site-packages\django\core\handlers\base.py", line 185, in _get_response
    response = wrapped_callback(request, *callback_args, **callback_kwargs)
  File "D:\python10\day78\bbs\blog\views.py", line 349, in up_down
    models.ArticleUpDown.objects.create(user=user,article_id=article_id,is_up=is_up)
  File "C:\Python36\lib\site-packages\django\db\models\manager.py", line 85, in manager_method
    return getattr(self.get_queryset(), name)(*args, **kwargs)
  File "C:\Python36\lib\site-packages\django\db\models\query.py", line 392, in create
    obj = self.model(**kwargs)
  File "C:\Python36\lib\site-packages\django\db\models\base.py", line 555, in __init__
    _setattr(self, field.name, rel_obj)
  File "C:\Python36\lib\site-packages\django\db\models\fields\related_descriptors.py", line 216, in __set__
    self.field.remote_field.model._meta.object_name,
ValueError: Cannot assign "<SimpleLazyObject: <django.contrib.auth.models.AnonymousUser object at 0x000000000BDAE9B0>>": "ArticleUpDown.user" must be a "UserInfo" instance.
[2018-05-28 10:49:05,554][Thread-20:7108][task_id:requests.packages.urllib3.connectionpool][connectionpool.py:214][INFO][Starting new HTTP connection (1): api.geetest.com]
[2018-05-28 10:49:22,398][Thread-21:3816][task_id:requests.packages.urllib3.connectionpool][connectionpool.py:214][INFO][Starting new HTTP connection (1): api.geetest.com]
[2018-05-29 08:38:27,049][Thread-8:7120][task_id:django.request][base.py:152][WARNING][Not Found: /favicon.ico]
[2018-05-29 08:55:22,891][Thread-21:1380][task_id:django.request][exception.py:135][ERROR][Internal Server Error: /blog/up_down/]
Traceback (most recent call last):
  File "D:\python10\day78\bbs\blog\views.py", line 352, in up_down
    models.ArticleUpDown.objects.create(user=user,article_id=article_id,is_up=is_up)
  File "C:\Python36\lib\site-packages\django\db\models\manager.py", line 85, in manager_method
    return getattr(self.get_queryset(), name)(*args, **kwargs)
  File "C:\Python36\lib\site-packages\django\db\models\query.py", line 394, in create
    obj.save(force_insert=True, using=self.db)
  File "C:\Python36\lib\site-packages\django\db\models\base.py", line 808, in save
    force_update=force_update, update_fields=update_fields)
  File "C:\Python36\lib\site-packages\django\db\models\base.py", line 838, in save_base
    updated = self._save_table(raw, cls, force_insert, force_update, using, update_fields)
  File "C:\Python36\lib\site-packages\django\db\models\base.py", line 924, in _save_table
    result = self._do_insert(cls._base_manager, using, fields, update_pk, raw)
  File "C:\Python36\lib\site-packages\django\db\models\base.py", line 963, in _do_insert
    using=using, raw=raw)
  File "C:\Python36\lib\site-packages\django\db\models\manager.py", line 85, in manager_method
    return getattr(self.get_queryset(), name)(*args, **kwargs)
  File "C:\Python36\lib\site-packages\django\db\models\query.py", line 1076, in _insert
    return query.get_compiler(using=using).execute_sql(return_id)
  File "C:\Python36\lib\site-packages\django\db\models\sql\compiler.py", line 1106, in execute_sql
    for sql, params in self.as_sql():
  File "C:\Python36\lib\site-packages\django\db\models\sql\compiler.py", line 1059, in as_sql
    for obj in self.query.objs
  File "C:\Python36\lib\site-packages\django\db\models\sql\compiler.py", line 1059, in <listcomp>
    for obj in self.query.objs
  File "C:\Python36\lib\site-packages\django\db\models\sql\compiler.py", line 1058, in <listcomp>
    [self.prepare_value(field, self.pre_save_val(field, obj)) for field in fields]
  File "C:\Python36\lib\site-packages\django\db\models\sql\compiler.py", line 998, in prepare_value
    value = field.get_db_prep_save(value, connection=self.connection)
  File "C:\Python36\lib\site-packages\django\db\models\fields\related.py", line 963, in get_db_prep_save
    return self.target_field.get_db_prep_save(value, connection=connection)
  File "C:\Python36\lib\site-packages\django\db\models\fields\__init__.py", line 770, in get_db_prep_save
    prepared=False)
  File "C:\Python36\lib\site-packages\django\db\models\fields\__init__.py", line 958, in get_db_prep_value
    value = self.get_prep_value(value)
  File "C:\Python36\lib\site-packages\django\db\models\fields\__init__.py", line 966, in get_prep_value
    return int(value)
ValueError: invalid literal for int() with base 10: '{{ article.pk }}'

During handling of the above exception, another exception occurred:

Traceback (most recent call last):
  File "C:\Python36\lib\site-packages\django\core\handlers\exception.py", line 41, in inner
    response = get_response(request)
  File "C:\Python36\lib\site-packages\django\core\handlers\base.py", line 187, in _get_response
    response = self.process_exception_by_middleware(e, request)
  File "C:\Python36\lib\site-packages\django\core\handlers\base.py", line 185, in _get_response
    response = wrapped_callback(request, *callback_args, **callback_kwargs)
  File "D:\python10\day78\bbs\blog\views.py", line 357, in up_down
    response["fisrt_action"]=models.ArticleUpDown.objects.filter(user=user,article_id=article_id).first().is_up
  File "C:\Python36\lib\site-packages\django\db\models\manager.py", line 85, in manager_method
    return getattr(self.get_queryset(), name)(*args, **kwargs)
  File "C:\Python36\lib\site-packages\django\db\models\query.py", line 784, in filter
    return self._filter_or_exclude(False, *args, **kwargs)
  File "C:\Python36\lib\site-packages\django\db\models\query.py", line 802, in _filter_or_exclude
    clone.query.add_q(Q(*args, **kwargs))
  File "C:\Python36\lib\site-packages\django\db\models\sql\query.py", line 1250, in add_q
    clause, _ = self._add_q(q_object, self.used_aliases)
  File "C:\Python36\lib\site-packages\django\db\models\sql\query.py", line 1276, in _add_q
    allow_joins=allow_joins, split_subq=split_subq,
  File "C:\Python36\lib\site-packages\django\db\models\sql\query.py", line 1206, in build_filter
    condition = lookup_class(lhs, value)
  File "C:\Python36\lib\site-packages\django\db\models\lookups.py", line 24, in __init__
    self.rhs = self.get_prep_lookup()
  File "C:\Python36\lib\site-packages\django\db\models\fields\related_lookups.py", line 112, in get_prep_lookup
    self.rhs = target_field.get_prep_value(self.rhs)
  File "C:\Python36\lib\site-packages\django\db\models\fields\__init__.py", line 966, in get_prep_value
    return int(value)
ValueError: invalid literal for int() with base 10: '{{ article.pk }}'
[2018-05-29 08:55:24,182][Thread-22:6636][task_id:django.request][exception.py:135][ERROR][Internal Server Error: /blog/up_down/]
Traceback (most recent call last):
  File "D:\python10\day78\bbs\blog\views.py", line 352, in up_down
    models.ArticleUpDown.objects.create(user=user,article_id=article_id,is_up=is_up)
  File "C:\Python36\lib\site-packages\django\db\models\manager.py", line 85, in manager_method
    return getattr(self.get_queryset(), name)(*args, **kwargs)
  File "C:\Python36\lib\site-packages\django\db\models\query.py", line 394, in create
    obj.save(force_insert=True, using=self.db)
  File "C:\Python36\lib\site-packages\django\db\models\base.py", line 808, in save
    force_update=force_update, update_fields=update_fields)
  File "C:\Python36\lib\site-packages\django\db\models\base.py", line 838, in save_base
    updated = self._save_table(raw, cls, force_insert, force_update, using, update_fields)
  File "C:\Python36\lib\site-packages\django\db\models\base.py", line 924, in _save_table
    result = self._do_insert(cls._base_manager, using, fields, update_pk, raw)
  File "C:\Python36\lib\site-packages\django\db\models\base.py", line 963, in _do_insert
    using=using, raw=raw)
  File "C:\Python36\lib\site-packages\django\db\models\manager.py", line 85, in manager_method
    return getattr(self.get_queryset(), name)(*args, **kwargs)
  File "C:\Python36\lib\site-packages\django\db\models\query.py", line 1076, in _insert
    return query.get_compiler(using=using).execute_sql(return_id)
  File "C:\Python36\lib\site-packages\django\db\models\sql\compiler.py", line 1106, in execute_sql
    for sql, params in self.as_sql():
  File "C:\Python36\lib\site-packages\django\db\models\sql\compiler.py", line 1059, in as_sql
    for obj in self.query.objs
  File "C:\Python36\lib\site-packages\django\db\models\sql\compiler.py", line 1059, in <listcomp>
    for obj in self.query.objs
  File "C:\Python36\lib\site-packages\django\db\models\sql\compiler.py", line 1058, in <listcomp>
    [self.prepare_value(field, self.pre_save_val(field, obj)) for field in fields]
  File "C:\Python36\lib\site-packages\django\db\models\sql\compiler.py", line 998, in prepare_value
    value = field.get_db_prep_save(value, connection=self.connection)
  File "C:\Python36\lib\site-packages\django\db\models\fields\related.py", line 963, in get_db_prep_save
    return self.target_field.get_db_prep_save(value, connection=connection)
  File "C:\Python36\lib\site-packages\django\db\models\fields\__init__.py", line 770, in get_db_prep_save
    prepared=False)
  File "C:\Python36\lib\site-packages\django\db\models\fields\__init__.py", line 958, in get_db_prep_value
    value = self.get_prep_value(value)
  File "C:\Python36\lib\site-packages\django\db\models\fields\__init__.py", line 966, in get_prep_value
    return int(value)
ValueError: invalid literal for int() with base 10: '{{ article.pk }}'

During handling of the above exception, another exception occurred:

Traceback (most recent call last):
  File "C:\Python36\lib\site-packages\django\core\handlers\exception.py", line 41, in inner
    response = get_response(request)
  File "C:\Python36\lib\site-packages\django\core\handlers\base.py", line 187, in _get_response
    response = self.process_exception_by_middleware(e, request)
  File "C:\Python36\lib\site-packages\django\core\handlers\base.py", line 185, in _get_response
    response = wrapped_callback(request, *callback_args, **callback_kwargs)
  File "D:\python10\day78\bbs\blog\views.py", line 357, in up_down
    response["fisrt_action"]=models.ArticleUpDown.objects.filter(user=user,article_id=article_id).first().is_up
  File "C:\Python36\lib\site-packages\django\db\models\manager.py", line 85, in manager_method
    return getattr(self.get_queryset(), name)(*args, **kwargs)
  File "C:\Python36\lib\site-packages\django\db\models\query.py", line 784, in filter
    return self._filter_or_exclude(False, *args, **kwargs)
  File "C:\Python36\lib\site-packages\django\db\models\query.py", line 802, in _filter_or_exclude
    clone.query.add_q(Q(*args, **kwargs))
  File "C:\Python36\lib\site-packages\django\db\models\sql\query.py", line 1250, in add_q
    clause, _ = self._add_q(q_object, self.used_aliases)
  File "C:\Python36\lib\site-packages\django\db\models\sql\query.py", line 1276, in _add_q
    allow_joins=allow_joins, split_subq=split_subq,
  File "C:\Python36\lib\site-packages\django\db\models\sql\query.py", line 1206, in build_filter
    condition = lookup_class(lhs, value)
  File "C:\Python36\lib\site-packages\django\db\models\lookups.py", line 24, in __init__
    self.rhs = self.get_prep_lookup()
  File "C:\Python36\lib\site-packages\django\db\models\fields\related_lookups.py", line 112, in get_prep_lookup
    self.rhs = target_field.get_prep_value(self.rhs)
  File "C:\Python36\lib\site-packages\django\db\models\fields\__init__.py", line 966, in get_prep_value
    return int(value)
ValueError: invalid literal for int() with base 10: '{{ article.pk }}'
[2018-05-29 08:55:25,009][Thread-23:7120][task_id:django.request][exception.py:135][ERROR][Internal Server Error: /blog/up_down/]
Traceback (most recent call last):
  File "D:\python10\day78\bbs\blog\views.py", line 352, in up_down
    models.ArticleUpDown.objects.create(user=user,article_id=article_id,is_up=is_up)
  File "C:\Python36\lib\site-packages\django\db\models\manager.py", line 85, in manager_method
    return getattr(self.get_queryset(), name)(*args, **kwargs)
  File "C:\Python36\lib\site-packages\django\db\models\query.py", line 394, in create
    obj.save(force_insert=True, using=self.db)
  File "C:\Python36\lib\site-packages\django\db\models\base.py", line 808, in save
    force_update=force_update, update_fields=update_fields)
  File "C:\Python36\lib\site-packages\django\db\models\base.py", line 838, in save_base
    updated = self._save_table(raw, cls, force_insert, force_update, using, update_fields)
  File "C:\Python36\lib\site-packages\django\db\models\base.py", line 924, in _save_table
    result = self._do_insert(cls._base_manager, using, fields, update_pk, raw)
  File "C:\Python36\lib\site-packages\django\db\models\base.py", line 963, in _do_insert
    using=using, raw=raw)
  File "C:\Python36\lib\site-packages\django\db\models\manager.py", line 85, in manager_method
    return getattr(self.get_queryset(), name)(*args, **kwargs)
  File "C:\Python36\lib\site-packages\django\db\models\query.py", line 1076, in _insert
    return query.get_compiler(using=using).execute_sql(return_id)
  File "C:\Python36\lib\site-packages\django\db\models\sql\compiler.py", line 1106, in execute_sql
    for sql, params in self.as_sql():
  File "C:\Python36\lib\site-packages\django\db\models\sql\compiler.py", line 1059, in as_sql
    for obj in self.query.objs
  File "C:\Python36\lib\site-packages\django\db\models\sql\compiler.py", line 1059, in <listcomp>
    for obj in self.query.objs
  File "C:\Python36\lib\site-packages\django\db\models\sql\compiler.py", line 1058, in <listcomp>
    [self.prepare_value(field, self.pre_save_val(field, obj)) for field in fields]
  File "C:\Python36\lib\site-packages\django\db\models\sql\compiler.py", line 998, in prepare_value
    value = field.get_db_prep_save(value, connection=self.connection)
  File "C:\Python36\lib\site-packages\django\db\models\fields\related.py", line 963, in get_db_prep_save
    return self.target_field.get_db_prep_save(value, connection=connection)
  File "C:\Python36\lib\site-packages\django\db\models\fields\__init__.py", line 770, in get_db_prep_save
    prepared=False)
  File "C:\Python36\lib\site-packages\django\db\models\fields\__init__.py", line 958, in get_db_prep_value
    value = self.get_prep_value(value)
  File "C:\Python36\lib\site-packages\django\db\models\fields\__init__.py", line 966, in get_prep_value
    return int(value)
ValueError: invalid literal for int() with base 10: '{{ article.pk }}'

During handling of the above exception, another exception occurred:

Traceback (most recent call last):
  File "C:\Python36\lib\site-packages\django\core\handlers\exception.py", line 41, in inner
    response = get_response(request)
  File "C:\Python36\lib\site-packages\django\core\handlers\base.py", line 187, in _get_response
    response = self.process_exception_by_middleware(e, request)
  File "C:\Python36\lib\site-packages\django\core\handlers\base.py", line 185, in _get_response
    response = wrapped_callback(request, *callback_args, **callback_kwargs)
  File "D:\python10\day78\bbs\blog\views.py", line 357, in up_down
    response["fisrt_action"]=models.ArticleUpDown.objects.filter(user=user,article_id=article_id).first().is_up
  File "C:\Python36\lib\site-packages\django\db\models\manager.py", line 85, in manager_method
    return getattr(self.get_queryset(), name)(*args, **kwargs)
  File "C:\Python36\lib\site-packages\django\db\models\query.py", line 784, in filter
    return self._filter_or_exclude(False, *args, **kwargs)
  File "C:\Python36\lib\site-packages\django\db\models\query.py", line 802, in _filter_or_exclude
    clone.query.add_q(Q(*args, **kwargs))
  File "C:\Python36\lib\site-packages\django\db\models\sql\query.py", line 1250, in add_q
    clause, _ = self._add_q(q_object, self.used_aliases)
  File "C:\Python36\lib\site-packages\django\db\models\sql\query.py", line 1276, in _add_q
    allow_joins=allow_joins, split_subq=split_subq,
  File "C:\Python36\lib\site-packages\django\db\models\sql\query.py", line 1206, in build_filter
    condition = lookup_class(lhs, value)
  File "C:\Python36\lib\site-packages\django\db\models\lookups.py", line 24, in __init__
    self.rhs = self.get_prep_lookup()
  File "C:\Python36\lib\site-packages\django\db\models\fields\related_lookups.py", line 112, in get_prep_lookup
    self.rhs = target_field.get_prep_value(self.rhs)
  File "C:\Python36\lib\site-packages\django\db\models\fields\__init__.py", line 966, in get_prep_value
    return int(value)
ValueError: invalid literal for int() with base 10: '{{ article.pk }}'
[2018-05-29 08:55:30,735][Thread-25:4484][task_id:django.request][exception.py:135][ERROR][Internal Server Error: /blog/up_down/]
Traceback (most recent call last):
  File "C:\Python36\lib\site-packages\django\core\handlers\exception.py", line 41, in inner
    response = get_response(request)
  File "C:\Python36\lib\site-packages\django\core\handlers\base.py", line 187, in _get_response
    response = self.process_exception_by_middleware(e, request)
  File "C:\Python36\lib\site-packages\django\core\handlers\base.py", line 185, in _get_response
    response = wrapped_callback(request, *callback_args, **callback_kwargs)
  File "D:\python10\day78\bbs\blog\views.py", line 347, in up_down
    is_up=json.loads(request.POST.get('is_up'))
  File "C:\Python36\lib\json\__init__.py", line 348, in loads
    'not {!r}'.format(s.__class__.__name__))
TypeError: the JSON object must be str, bytes or bytearray, not 'NoneType'
[2018-05-29 08:58:31,421][Thread-43:6968][task_id:requests.packages.urllib3.connectionpool][connectionpool.py:214][INFO][Starting new HTTP connection (1): api.geetest.com]
[2018-05-29 08:58:34,173][Thread-46:6168][task_id:requests.packages.urllib3.connectionpool][connectionpool.py:214][INFO][Starting new HTTP connection (1): api.geetest.com]
[2018-05-29 09:04:03,453][Thread-88:2884][task_id:requests.packages.urllib3.connectionpool][connectionpool.py:214][INFO][Starting new HTTP connection (1): api.geetest.com]
[2018-05-29 09:04:20,772][Thread-90:1648][task_id:requests.packages.urllib3.connectionpool][connectionpool.py:214][INFO][Starting new HTTP connection (1): api.geetest.com]
[2018-05-29 09:04:38,775][Thread-91:6972][task_id:requests.packages.urllib3.connectionpool][connectionpool.py:214][INFO][Starting new HTTP connection (1): api.geetest.com]
[2018-05-29 09:12:48,949][Thread-7:1568][task_id:django.security.csrf][csrf.py:160][WARNING][Forbidden (CSRF token missing or incorrect.): /blog/comment/]
[2018-05-29 10:20:23,240][Thread-61:6536][task_id:requests.packages.urllib3.connectionpool][connectionpool.py:214][INFO][Starting new HTTP connection (1): api.geetest.com]
[2018-05-29 10:20:36,804][Thread-63:5328][task_id:requests.packages.urllib3.connectionpool][connectionpool.py:214][INFO][Starting new HTTP connection (1): api.geetest.com]
[2018-05-29 10:21:36,228][Thread-94:5800][task_id:requests.packages.urllib3.connectionpool][connectionpool.py:214][INFO][Starting new HTTP connection (1): api.geetest.com]
[2018-05-29 10:21:45,728][Thread-95:5328][task_id:requests.packages.urllib3.connectionpool][connectionpool.py:214][INFO][Starting new HTTP connection (1): api.geetest.com]
[2018-05-29 10:33:24,161][Thread-166:7024][task_id:django.request][exception.py:135][ERROR][Internal Server Error: /blog/comment/]
Traceback (most recent call last):
  File "C:\Python36\lib\site-packages\django\core\handlers\exception.py", line 41, in inner
    response = get_response(request)
  File "C:\Python36\lib\site-packages\django\core\handlers\base.py", line 187, in _get_response
    response = self.process_exception_by_middleware(e, request)
  File "C:\Python36\lib\site-packages\django\core\handlers\base.py", line 185, in _get_response
    response = wrapped_callback(request, *callback_args, **callback_kwargs)
  File "D:\python10\day78\bbs\blog\views.py", line 394, in comment
    response["create_time"]=comment_obj.create_time
UnboundLocalError: local variable 'comment_obj' referenced before assignment
[2018-05-29 10:33:25,360][Thread-167:5708][task_id:django.request][exception.py:135][ERROR][Internal Server Error: /blog/comment/]
Traceback (most recent call last):
  File "C:\Python36\lib\site-packages\django\core\handlers\exception.py", line 41, in inner
    response = get_response(request)
  File "C:\Python36\lib\site-packages\django\core\handlers\base.py", line 187, in _get_response
    response = self.process_exception_by_middleware(e, request)
  File "C:\Python36\lib\site-packages\django\core\handlers\base.py", line 185, in _get_response
    response = wrapped_callback(request, *callback_args, **callback_kwargs)
  File "D:\python10\day78\bbs\blog\views.py", line 394, in comment
    response["create_time"]=comment_obj.create_time
UnboundLocalError: local variable 'comment_obj' referenced before assignment
[2018-05-29 10:33:40,798][Thread-172:1684][task_id:django.request][exception.py:135][ERROR][Internal Server Error: /blog/comment/]
Traceback (most recent call last):
  File "C:\Python36\lib\site-packages\django\db\backends\utils.py", line 65, in execute
    return self.cursor.execute(sql, params)
  File "C:\Python36\lib\site-packages\django\db\backends\mysql\base.py", line 101, in execute
    return self.cursor.execute(query, args)
  File "C:\Python36\lib\site-packages\pymysql\cursors.py", line 165, in execute
    result = self._query(query)
  File "C:\Python36\lib\site-packages\pymysql\cursors.py", line 321, in _query
    conn.query(q)
  File "C:\Python36\lib\site-packages\pymysql\connections.py", line 860, in query
    self._affected_rows = self._read_query_result(unbuffered=unbuffered)
  File "C:\Python36\lib\site-packages\pymysql\connections.py", line 1061, in _read_query_result
    result.read()
  File "C:\Python36\lib\site-packages\pymysql\connections.py", line 1349, in read
    first_packet = self.connection._read_packet()
  File "C:\Python36\lib\site-packages\pymysql\connections.py", line 1018, in _read_packet
    packet.check_error()
  File "C:\Python36\lib\site-packages\pymysql\connections.py", line 384, in check_error
    err.raise_mysql_exception(self._data)
  File "C:\Python36\lib\site-packages\pymysql\err.py", line 107, in raise_mysql_exception
    raise errorclass(errno, errval)
pymysql.err.IntegrityError: (1048, "Column 'article_id' cannot be null")

The above exception was the direct cause of the following exception:

Traceback (most recent call last):
  File "C:\Python36\lib\site-packages\django\core\handlers\exception.py", line 41, in inner
    response = get_response(request)
  File "C:\Python36\lib\site-packages\django\core\handlers\base.py", line 187, in _get_response
    response = self.process_exception_by_middleware(e, request)
  File "C:\Python36\lib\site-packages\django\core\handlers\base.py", line 185, in _get_response
    response = wrapped_callback(request, *callback_args, **callback_kwargs)
  File "D:\python10\day78\bbs\blog\views.py", line 391, in comment
    comment_obj=models.Comment.objects.create(article_id=article_id,user_id=user_pk,content=content)
  File "C:\Python36\lib\site-packages\django\db\models\manager.py", line 85, in manager_method
    return getattr(self.get_queryset(), name)(*args, **kwargs)
  File "C:\Python36\lib\site-packages\django\db\models\query.py", line 394, in create
    obj.save(force_insert=True, using=self.db)
  File "C:\Python36\lib\site-packages\django\db\models\base.py", line 808, in save
    force_update=force_update, update_fields=update_fields)
  File "C:\Python36\lib\site-packages\django\db\models\base.py", line 838, in save_base
    updated = self._save_table(raw, cls, force_insert, force_update, using, update_fields)
  File "C:\Python36\lib\site-packages\django\db\models\base.py", line 924, in _save_table
    result = self._do_insert(cls._base_manager, using, fields, update_pk, raw)
  File "C:\Python36\lib\site-packages\django\db\models\base.py", line 963, in _do_insert
    using=using, raw=raw)
  File "C:\Python36\lib\site-packages\django\db\models\manager.py", line 85, in manager_method
    return getattr(self.get_queryset(), name)(*args, **kwargs)
  File "C:\Python36\lib\site-packages\django\db\models\query.py", line 1076, in _insert
    return query.get_compiler(using=using).execute_sql(return_id)
  File "C:\Python36\lib\site-packages\django\db\models\sql\compiler.py", line 1107, in execute_sql
    cursor.execute(sql, params)
  File "C:\Python36\lib\site-packages\django\db\backends\utils.py", line 80, in execute
    return super(CursorDebugWrapper, self).execute(sql, params)
  File "C:\Python36\lib\site-packages\django\db\backends\utils.py", line 65, in execute
    return self.cursor.execute(sql, params)
  File "C:\Python36\lib\site-packages\django\db\utils.py", line 94, in __exit__
    six.reraise(dj_exc_type, dj_exc_value, traceback)
  File "C:\Python36\lib\site-packages\django\utils\six.py", line 685, in reraise
    raise value.with_traceback(tb)
  File "C:\Python36\lib\site-packages\django\db\backends\utils.py", line 65, in execute
    return self.cursor.execute(sql, params)
  File "C:\Python36\lib\site-packages\django\db\backends\mysql\base.py", line 101, in execute
    return self.cursor.execute(query, args)
  File "C:\Python36\lib\site-packages\pymysql\cursors.py", line 165, in execute
    result = self._query(query)
  File "C:\Python36\lib\site-packages\pymysql\cursors.py", line 321, in _query
    conn.query(q)
  File "C:\Python36\lib\site-packages\pymysql\connections.py", line 860, in query
    self._affected_rows = self._read_query_result(unbuffered=unbuffered)
  File "C:\Python36\lib\site-packages\pymysql\connections.py", line 1061, in _read_query_result
    result.read()
  File "C:\Python36\lib\site-packages\pymysql\connections.py", line 1349, in read
    first_packet = self.connection._read_packet()
  File "C:\Python36\lib\site-packages\pymysql\connections.py", line 1018, in _read_packet
    packet.check_error()
  File "C:\Python36\lib\site-packages\pymysql\connections.py", line 384, in check_error
    err.raise_mysql_exception(self._data)
  File "C:\Python36\lib\site-packages\pymysql\err.py", line 107, in raise_mysql_exception
    raise errorclass(errno, errval)
django.db.utils.IntegrityError: (1048, "Column 'article_id' cannot be null")
[2018-05-29 10:35:59,178][Thread-203:4820][task_id:django.request][exception.py:135][ERROR][Internal Server Error: /blog/comment/]
Traceback (most recent call last):
  File "C:\Python36\lib\site-packages\django\core\handlers\exception.py", line 41, in inner
    response = get_response(request)
  File "C:\Python36\lib\site-packages\django\core\handlers\base.py", line 187, in _get_response
    response = self.process_exception_by_middleware(e, request)
  File "C:\Python36\lib\site-packages\django\core\handlers\base.py", line 185, in _get_response
    response = wrapped_callback(request, *callback_args, **callback_kwargs)
  File "D:\python10\day78\bbs\blog\views.py", line 394, in comment
    response["create_time"]=comment_obj.create_time
UnboundLocalError: local variable 'comment_obj' referenced before assignment
[2018-05-29 10:41:31,647][Thread-26:2916][task_id:django.request][exception.py:135][ERROR][Internal Server Error: /blog/comment/]
Traceback (most recent call last):
  File "C:\Python36\lib\site-packages\django\core\handlers\exception.py", line 41, in inner
    response = get_response(request)
  File "C:\Python36\lib\site-packages\django\core\handlers\base.py", line 187, in _get_response
    response = self.process_exception_by_middleware(e, request)
  File "C:\Python36\lib\site-packages\django\core\handlers\base.py", line 185, in _get_response
    response = wrapped_callback(request, *callback_args, **callback_kwargs)
  File "D:\python10\day78\bbs\blog\views.py", line 394, in comment
    response["create_time"]=comment_obj.create_time.strftime("%Y-%m-%d")
UnboundLocalError: local variable 'comment_obj' referenced before assignment
[2018-05-29 11:31:08,523][Thread-15:4084][task_id:django.request][exception.py:135][ERROR][Internal Server Error: /blog/comment_tree/3]
Traceback (most recent call last):
  File "C:\Python36\lib\site-packages\django\core\handlers\exception.py", line 41, in inner
    response = get_response(request)
  File "C:\Python36\lib\site-packages\django\core\handlers\base.py", line 187, in _get_response
    response = self.process_exception_by_middleware(e, request)
  File "C:\Python36\lib\site-packages\django\core\handlers\base.py", line 185, in _get_response
    response = wrapped_callback(request, *callback_args, **callback_kwargs)
  File "D:\python10\day78\bbs\blog\views.py", line 410, in comment_tree
    return JsonResponse("")
TypeError: __init__() missing 1 required positional argument: 'data'
[2018-05-29 11:31:25,942][Thread-14:6496][task_id:blog.views][views.py:249][WARNING][又有人访问不存在页面了...]
[2018-05-29 11:32:05,213][Thread-26:5124][task_id:django.request][exception.py:135][ERROR][Internal Server Error: /blog/comment_tree/3/]
Traceback (most recent call last):
  File "C:\Python36\lib\site-packages\django\core\handlers\exception.py", line 41, in inner
    response = get_response(request)
  File "C:\Python36\lib\site-packages\django\core\handlers\base.py", line 187, in _get_response
    response = self.process_exception_by_middleware(e, request)
  File "C:\Python36\lib\site-packages\django\core\handlers\base.py", line 185, in _get_response
    response = wrapped_callback(request, *callback_args, **callback_kwargs)
  File "D:\python10\day78\bbs\blog\views.py", line 410, in comment_tree
    return JsonResponse("")
  File "C:\Python36\lib\site-packages\django\http\response.py", line 524, in __init__
    'In order to allow non-dict objects to be serialized set the '
TypeError: In order to allow non-dict objects to be serialized set the safe parameter to False.
[2018-05-30 08:33:45,396][Thread-6:2176][task_id:django.request][base.py:152][WARNING][Not Found: /favicon.ico]
[2018-05-30 09:10:12,445][Thread-3:6540][task_id:django.security.csrf][csrf.py:160][WARNING][Forbidden (CSRF token missing or incorrect.): /upload/]
[2018-05-30 10:28:13,462][Thread-18:6524][task_id:blog.views][views.py:249][WARNING][又有人访问不存在页面了...]
[2018-05-30 12:15:02,440][Thread-16:1300][task_id:django.request][base.py:152][WARNING][Not Found: /query]
[2018-05-30 12:15:02,660][Thread-17:5332][task_id:django.request][base.py:152][WARNING][Not Found: /favicon.ico]
[2019-01-20 20:16:38,395][Thread-8:9124][task_id:django.request][base.py:152][WARNING][Not Found: /favicon.ico]
[2019-01-20 20:17:02,065][Thread-16:10920][task_id:django.request][base.py:152][WARNING][Not Found: /favicon.ico]
[2019-01-20 20:30:45,614][Thread-92:22880][task_id:django.request][base.py:152][WARNING][Not Found: /favicon.ico]
[2019-01-20 20:31:09,267][Thread-96:20776][task_id:blog.views][views.py:249][WARNING][又有人访问不存在页面了...]
[2019-01-20 20:31:09,520][Thread-97:13476][task_id:django.request][base.py:152][WARNING][Not Found: /favicon.ico]
[2019-01-20 20:32:44,600][Thread-109:22988][task_id:django.request][base.py:152][WARNING][Not Found: /favicon.ico]
[2019-01-20 20:33:54,884][Thread-118:17532][task_id:django.request][base.py:152][WARNING][Not Found: /favicon.ico]
[2019-01-20 20:42:11,517][Thread-128:22300][task_id:django.request][base.py:152][WARNING][Not Found: /favicon.ico]
[2019-01-20 20:47:11,632][Thread-30:8320][task_id:django.request][base.py:152][WARNING][Not Found: /favicon.ico]
[2019-01-20 20:48:39,973][Thread-40:1264][task_id:django.request][base.py:152][WARNING][Not Found: /favicon.ico]
[2019-01-20 20:50:41,630][Thread-46:19628][task_id:django.request][base.py:152][WARNING][Not Found: /favicon.ico]
[2019-01-20 20:51:41,503][Thread-59:14776][task_id:django.request][base.py:152][WARNING][Not Found: /favicon.ico]
[2019-01-20 20:53:02,229][Thread-70:4008][task_id:django.request][base.py:152][WARNING][Not Found: /WillieChen]
[2019-01-20 21:02:29,781][Thread-109:23252][task_id:blog.views][views.py:249][WARNING][又有人访问不存在页面了...]
[2019-01-20 23:20:28,979][Thread-9:22320][task_id:django.request][base.py:152][WARNING][Not Found: /favicon.ico]
[2019-01-20 23:25:04,170][Thread-35:20328][task_id:django.request][base.py:152][WARNING][Not Found: /favicon.ico]
[2019-01-20 23:25:42,311][Thread-42:20736][task_id:django.request][base.py:152][WARNING][Not Found: /favicon.ico]
[2019-01-22 19:42:20,031][Thread-6:17900][task_id:django.request][base.py:152][WARNING][Not Found: /favicon.ico]
[2019-01-22 19:42:46,112][Thread-16:19108][task_id:django.request][base.py:152][WARNING][Not Found: /favicon.ico]
[2019-01-22 22:16:41,418][Thread-8:23520][task_id:django.request][base.py:152][WARNING][Not Found: /favicon.ico]
[2019-01-23 00:40:10,867][Thread-7:13856][task_id:django.request][base.py:152][WARNING][Not Found: /favicon.ico]
[2019-01-23 00:40:26,961][Thread-9:18164][task_id:django.request][base.py:152][WARNING][Not Found: /add_article]
[2019-01-23 00:40:28,191][Thread-10:22408][task_id:django.request][base.py:152][WARNING][Not Found: /favicon.ico]
[2019-01-23 00:40:56,281][Thread-11:13808][task_id:blog.views][views.py:139][WARNING][又有人訪問不存在的頁面了...]
[2019-01-23 00:42:32,590][Thread-19:6408][task_id:django.request][base.py:152][WARNING][Not Found: /backend/add_article]
[2019-01-23 00:42:57,868][Thread-22:16700][task_id:django.request][base.py:152][WARNING][Not Found: /favicon.ico]
[2019-01-23 00:46:23,946][Thread-41:8492][task_id:django.request][base.py:152][WARNING][Not Found: /favicon.ico]
[2019-01-23 01:15:10,457][Thread-174:23968][task_id:django.request][base.py:152][WARNING][Not Found: /favicon.ico]
[2019-01-23 01:22:39,649][Thread-209:17360][task_id:django.request][base.py:152][WARNING][Not Found: /favicon.ico]
[2019-01-23 01:33:27,439][Thread-268:16828][task_id:django.request][base.py:152][WARNING][Not Found: /favicon.ico]
[2019-01-23 01:34:26,656][Thread-274:16148][task_id:django.request][base.py:152][WARNING][Not Found: /favicon.ico]
[2019-01-23 01:59:03,415][Thread-1:15680][task_id:django.request][base.py:152][WARNING][Not Found: /blog/陈道明/article/3]
[2019-01-23 01:59:22,459][Thread-3:18160][task_id:django.request][base.py:152][WARNING][Not Found: /blog/陈道明/article/3]
[2019-01-23 01:59:26,084][Thread-4:5248][task_id:django.request][base.py:152][WARNING][Not Found: /blog/陈道明/article/3]
[2019-01-23 01:59:28,803][Thread-5:23980][task_id:django.request][base.py:152][WARNING][Not Found: /blog/陈道明/article/3]
[2019-01-23 01:59:30,961][Thread-6:24352][task_id:django.request][base.py:152][WARNING][Not Found: /blog/陈道明/article/3]
[2019-01-23 01:59:37,163][Thread-7:23636][task_id:django.request][base.py:152][WARNING][Not Found: /blog/陈道明/article/3/]
[2019-01-23 02:04:58,676][Thread-1:19760][task_id:django.request][base.py:152][WARNING][Not Found: /index/]
[2019-01-23 02:04:59,147][Thread-6:17384][task_id:django.request][base.py:152][WARNING][Not Found: /favicon.ico]
[2019-01-23 02:05:04,023][Thread-8:7840][task_id:django.request][base.py:152][WARNING][Not Found: /index/]
[2019-01-23 02:05:54,210][Thread-9:4500][task_id:django.request][base.py:152][WARNING][Not Found: /index/]
[2019-01-23 02:06:01,031][Thread-10:16184][task_id:django.request][base.py:152][WARNING][Not Found: /]
[2019-01-23 02:19:57,291][Thread-11:19604][task_id:django.request][base.py:152][WARNING][Not Found: /favicon.ico]
[2019-01-23 02:23:40,412][Thread-25:6452][task_id:blog.views][views.py:139][WARNING][又有人訪問不存在的頁面了...]
[2019-01-23 02:23:47,379][Thread-26:18492][task_id:blog.views][views.py:139][WARNING][又有人訪問不存在的頁面了...]
[2019-01-23 02:23:47,584][Thread-27:22028][task_id:django.request][base.py:152][WARNING][Not Found: /favicon.ico]
[2019-01-23 02:24:02,881][Thread-33:11924][task_id:blog.views][views.py:139][WARNING][又有人訪問不存在的頁面了...]
[2019-01-23 02:25:34,596][Thread-40:19008][task_id:django.request][base.py:152][WARNING][Not Found: /blog/WillieChen/]
[2019-01-23 02:26:52,816][Thread-41:15240][task_id:django.request][base.py:152][WARNING][Not Found: /blog/WillieChen/]
[2019-01-23 02:26:56,799][Thread-42:21052][task_id:django.request][base.py:152][WARNING][Not Found: /blog/WillieChen/]
[2019-01-23 12:46:01,364][Thread-9:18880][task_id:django.request][base.py:152][WARNING][Not Found: /favicon.ico]
[2019-01-23 12:46:11,379][Thread-19:24536][task_id:django.request][base.py:152][WARNING][Not Found: /favicon.ico]
[2019-01-23 12:46:54,198][Thread-43:6660][task_id:django.request][base.py:152][WARNING][Not Found: /favicon.ico]
[2019-01-23 12:47:19,210][Thread-58:12544][task_id:django.request][base.py:152][WARNING][Not Found: /favicon.ico]
[2019-01-23 12:47:43,381][Thread-73:12780][task_id:django.request][base.py:152][WARNING][Not Found: /favicon.ico]
[2019-01-23 13:21:02,310][Thread-11:6988][task_id:django.request][base.py:152][WARNING][Not Found: /favicon.ico]
[2019-01-23 13:21:06,620][Thread-15:11500][task_id:django.request][base.py:152][WARNING][Not Found: /favicon.ico]
[2019-01-23 13:22:04,033][Thread-46:20580][task_id:django.request][base.py:152][WARNING][Not Found: /favicon.ico]
[2019-01-23 13:22:38,190][Thread-62:1060][task_id:django.request][base.py:152][WARNING][Not Found: /favicon.ico]
[2019-01-23 13:22:50,166][Thread-65:24156][task_id:django.request][base.py:152][WARNING][Not Found: /favicon.ico]
[2019-01-23 13:24:19,875][Thread-67:18524][task_id:django.request][base.py:152][WARNING][Not Found: /favicon.ico]
[2019-01-23 13:24:26,713][Thread-73:21828][task_id:django.request][base.py:152][WARNING][Not Found: /favicon.ico]
[2019-01-23 13:24:31,921][Thread-78:15460][task_id:django.request][base.py:152][WARNING][Not Found: /favicon.ico]
[2019-01-23 13:28:19,101][Thread-107:10556][task_id:django.request][base.py:152][WARNING][Not Found: /favicon.ico]
[2019-01-23 13:30:34,319][Thread-148:19820][task_id:django.request][base.py:152][WARNING][Not Found: /favicon.ico]
[2019-01-23 13:31:54,060][Thread-174:12908][task_id:django.request][base.py:152][WARNING][Not Found: /favicon.ico]
[2019-01-23 13:32:16,568][Thread-187:22568][task_id:django.request][base.py:152][WARNING][Not Found: /favicon.ico]
[2019-01-23 13:32:48,924][Thread-201:22288][task_id:django.request][base.py:152][WARNING][Not Found: /favicon.ico]
[2019-01-23 13:34:35,426][Thread-14:10688][task_id:django.request][base.py:152][WARNING][Not Found: /favicon.ico]
[2019-01-23 13:35:53,025][Thread-32:17320][task_id:django.request][base.py:152][WARNING][Not Found: /favicon.ico]
[2019-01-23 13:36:09,087][Thread-40:3300][task_id:django.request][base.py:152][WARNING][Not Found: /favicon.ico]
[2019-01-23 13:36:39,013][Thread-56:19480][task_id:django.request][base.py:152][WARNING][Not Found: /favicon.ico]
[2019-01-23 13:41:44,904][Thread-92:15860][task_id:django.request][base.py:152][WARNING][Not Found: /favicon.ico]
[2019-01-23 13:53:28,663][Thread-42:5296][task_id:django.request][base.py:152][WARNING][Not Found: /favicon.ico]
[2019-01-23 15:45:28,768][Thread-14:13072][task_id:django.request][base.py:152][WARNING][Not Found: /favicon.ico]
[2019-01-23 16:18:50,573][Thread-15:16592][task_id:django.request][base.py:152][WARNING][Not Found: /favicon.ico]
[2019-01-23 16:48:27,284][Thread-113:15508][task_id:django.request][base.py:152][WARNING][Not Found: /favicon.ico]
[2019-01-23 19:05:01,956][Thread-9:6540][task_id:django.request][base.py:152][WARNING][Not Found: /favicon.ico]
[2019-01-23 21:35:28,363][Thread-11:16844][task_id:django.request][base.py:152][WARNING][Not Found: /favicon.ico]
[2019-01-23 22:04:02,786][Thread-40:17632][task_id:django.request][base.py:152][WARNING][Not Found: /favicon.ico]
[2019-01-23 22:04:17,847][Thread-46:11340][task_id:django.request][base.py:152][WARNING][Not Found: /favicon.ico]
[2019-01-23 22:04:24,054][Thread-54:19408][task_id:django.request][base.py:152][WARNING][Not Found: /favicon.ico]
[2019-01-23 23:36:32,947][Thread-87:19848][task_id:django.request][base.py:152][WARNING][Not Found: /favicon.ico]
[2019-01-23 23:37:04,437][Thread-93:22572][task_id:django.request][base.py:152][WARNING][Not Found: /favicon.ico]
[2019-01-24 00:29:38,002][Thread-102:16192][task_id:django.request][base.py:152][WARNING][Not Found: /favicon.ico]
[2019-01-24 10:34:49,499][Thread-10:14152][task_id:django.request][base.py:152][WARNING][Not Found: /favicon.ico]
[2019-01-24 10:35:08,285][Thread-17:19776][task_id:django.request][base.py:152][WARNING][Not Found: /favicon.ico]
[2019-01-24 10:35:14,848][Thread-19:2372][task_id:django.request][base.py:152][WARNING][Not Found: /favicon.ico]
[2019-01-24 10:35:19,342][Thread-24:12296][task_id:django.request][base.py:152][WARNING][Not Found: /favicon.ico]
[2019-01-24 19:30:07,090][Thread-29:19112][task_id:django.request][base.py:152][WARNING][Not Found: /favicon.ico]
[2019-01-24 19:34:57,193][Thread-77:6700][task_id:django.request][base.py:152][WARNING][Not Found: /favicon.ico]
[2019-01-24 23:16:10,356][Thread-135:10852][task_id:django.request][base.py:152][WARNING][Not Found: /favicon.ico]
[2019-01-24 23:18:05,611][Thread-137:21464][task_id:django.request][base.py:152][WARNING][Not Found: /backend/add_article]
[2019-01-24 23:18:32,996][Thread-139:18220][task_id:django.request][base.py:152][WARNING][Not Found: /favicon.ico]
[2019-01-24 23:25:28,874][Thread-145:15548][task_id:django.request][base.py:152][WARNING][Not Found: /favicon.ico]
[2019-01-24 23:39:37,121][Thread-165:18056][task_id:django.request][base.py:152][WARNING][Not Found: /favicon.ico]
[2019-01-25 00:39:03,021][Thread-180:12764][task_id:django.request][base.py:152][WARNING][Not Found: /favicon.ico]
[2019-01-25 00:39:06,248][Thread-183:15996][task_id:django.request][base.py:152][WARNING][Not Found: /favicon.ico]
[2019-01-25 00:56:31,313][Thread-192:16176][task_id:django.request][base.py:152][WARNING][Not Found: /favicon.ico]
[2019-01-25 01:04:47,334][Thread-195:16552][task_id:django.request][base.py:152][WARNING][Not Found: /favicon.ico]
[2019-01-25 01:21:52,939][Thread-50:23676][task_id:django.request][base.py:152][WARNING][Not Found: /favicon.ico]
[2019-01-25 01:22:11,610][Thread-60:13876][task_id:django.request][base.py:152][WARNING][Not Found: /favicon.ico]
[2019-01-25 01:24:15,671][Thread-69:10028][task_id:django.request][base.py:152][WARNING][Not Found: /favicon.ico]
[2019-01-25 01:26:24,408][Thread-88:14624][task_id:django.request][base.py:152][WARNING][Not Found: /favicon.ico]
[2019-01-25 01:26:29,190][Thread-97:22468][task_id:django.request][base.py:152][WARNING][Not Found: /favicon.ico]
[2019-01-25 01:26:51,460][Thread-106:18492][task_id:django.request][base.py:152][WARNING][Not Found: /favicon.ico]
[2019-01-25 01:28:27,639][Thread-115:17088][task_id:django.request][base.py:152][WARNING][Not Found: /favicon.ico]
[2019-01-25 01:43:37,256][Thread-170:16472][task_id:django.request][base.py:152][WARNING][Not Found: /favicon.ico]
[2019-01-25 02:30:49,935][Thread-183:19048][task_id:django.request][base.py:152][WARNING][Not Found: /favicon.ico]
